[2024-11-04T20:18:25.126+0000] {local_task_job_runner.py:123} INFO - ::group::Pre task execution logs
[2024-11-04T20:18:25.136+0000] {taskinstance.py:2612} INFO - Dependencies all met for dep_context=non-requeueable deps ti=<TaskInstance: backup_files_dag.backup_files manual__2024-11-04T20:18:23.163142+00:00 [queued]>
[2024-11-04T20:18:25.141+0000] {taskinstance.py:2612} INFO - Dependencies all met for dep_context=requeueable deps ti=<TaskInstance: backup_files_dag.backup_files manual__2024-11-04T20:18:23.163142+00:00 [queued]>
[2024-11-04T20:18:25.142+0000] {taskinstance.py:2865} INFO - Starting attempt 1 of 2
[2024-11-04T20:18:25.150+0000] {taskinstance.py:2888} INFO - Executing <Task(BashOperator): backup_files> on 2024-11-04 20:18:23.163142+00:00
[2024-11-04T20:18:25.156+0000] {warnings.py:112} WARNING - /home/***/.local/lib/python3.12/site-packages/***/task/task_runner/standard_task_runner.py:70: DeprecationWarning: This process (pid=103) is multi-threaded, use of fork() may lead to deadlocks in the child.
  pid = os.fork()

[2024-11-04T20:18:25.158+0000] {standard_task_runner.py:72} INFO - Started process 105 to run task
[2024-11-04T20:18:25.157+0000] {standard_task_runner.py:104} INFO - Running: ['***', 'tasks', 'run', 'backup_files_dag', 'backup_files', 'manual__2024-11-04T20:18:23.163142+00:00', '--job-id', '53', '--raw', '--subdir', 'DAGS_FOLDER/backup_files_dag.py', '--cfg-path', '/tmp/tmpbfjb4cje']
[2024-11-04T20:18:25.158+0000] {standard_task_runner.py:105} INFO - Job 53: Subtask backup_files
[2024-11-04T20:18:25.195+0000] {task_command.py:467} INFO - Running <TaskInstance: backup_files_dag.backup_files manual__2024-11-04T20:18:23.163142+00:00 [running]> on host e07dba6ee931
[2024-11-04T20:18:25.248+0000] {taskinstance.py:3131} INFO - Exporting env vars: AIRFLOW_CTX_DAG_OWNER='***' AIRFLOW_CTX_DAG_ID='backup_files_dag' AIRFLOW_CTX_TASK_ID='backup_files' AIRFLOW_CTX_EXECUTION_DATE='2024-11-04T20:18:23.163142+00:00' AIRFLOW_CTX_TRY_NUMBER='1' AIRFLOW_CTX_DAG_RUN_ID='manual__2024-11-04T20:18:23.163142+00:00'
[2024-11-04T20:18:25.249+0000] {logging_mixin.py:190} INFO - Task instance is in running state
[2024-11-04T20:18:25.250+0000] {logging_mixin.py:190} INFO -  Previous state of the Task instance: queued
[2024-11-04T20:18:25.251+0000] {logging_mixin.py:190} INFO - Current task name:backup_files state:running start_date:2024-11-04 20:18:25.137525+00:00
[2024-11-04T20:18:25.251+0000] {logging_mixin.py:190} INFO - Dag name:backup_files_dag and current dag run status:running
[2024-11-04T20:18:25.252+0000] {taskinstance.py:731} INFO - ::endgroup::
[2024-11-04T20:18:25.253+0000] {subprocess.py:63} INFO - Tmp dir root location: /tmp
[2024-11-04T20:18:25.254+0000] {subprocess.py:75} INFO - Running command: ['/usr/bin/bash', '-c', 'cp -r D:\\Dev\\Airflow\\source* D:\\Dev\\Airflow\\copy']
[2024-11-04T20:18:25.261+0000] {subprocess.py:86} INFO - Output:
[2024-11-04T20:18:25.263+0000] {subprocess.py:93} INFO - cp: cannot stat 'D:DevAirflowsource*': No such file or directory
[2024-11-04T20:18:25.264+0000] {subprocess.py:97} INFO - Command exited with return code 1
[2024-11-04T20:18:25.273+0000] {taskinstance.py:3310} ERROR - Task failed with exception
Traceback (most recent call last):
  File "/home/airflow/.local/lib/python3.12/site-packages/airflow/models/taskinstance.py", line 767, in _execute_task
    result = _execute_callable(context=context, **execute_callable_kwargs)
             ^^^^^^^^^^^^^^^^^^^^^^^^^^^^^^^^^^^^^^^^^^^^^^^^^^^^^^^^^^^^^
  File "/home/airflow/.local/lib/python3.12/site-packages/airflow/models/taskinstance.py", line 733, in _execute_callable
    return ExecutionCallableRunner(
           ^^^^^^^^^^^^^^^^^^^^^^^^
  File "/home/airflow/.local/lib/python3.12/site-packages/airflow/utils/operator_helpers.py", line 252, in run
    return self.func(*args, **kwargs)
           ^^^^^^^^^^^^^^^^^^^^^^^^^^
  File "/home/airflow/.local/lib/python3.12/site-packages/airflow/models/baseoperator.py", line 406, in wrapper
    return func(self, *args, **kwargs)
           ^^^^^^^^^^^^^^^^^^^^^^^^^^^
  File "/home/airflow/.local/lib/python3.12/site-packages/airflow/operators/bash.py", line 249, in execute
    raise AirflowException(
airflow.exceptions.AirflowException: Bash command failed. The command returned a non-zero exit code 1.
[2024-11-04T20:18:25.280+0000] {logging_mixin.py:190} INFO - Task instance in failure state
[2024-11-04T20:18:25.281+0000] {logging_mixin.py:190} INFO - Task start:2024-11-04 20:18:25.137525+00:00 end:2024-11-04 20:18:25.279970+00:00 duration:0.142445
[2024-11-04T20:18:25.281+0000] {logging_mixin.py:190} INFO - Task:<Task(BashOperator): backup_files> dag:<DAG: backup_files_dag> dagrun:<DagRun backup_files_dag @ 2024-11-04 20:18:23.163142+00:00: manual__2024-11-04T20:18:23.163142+00:00, state:running, queued_at: 2024-11-04 20:18:23.188080+00:00. externally triggered: True>
[2024-11-04T20:18:25.282+0000] {logging_mixin.py:190} INFO - Failure caused by Bash command failed. The command returned a non-zero exit code 1.
[2024-11-04T20:18:25.282+0000] {taskinstance.py:1225} INFO - Marking task as UP_FOR_RETRY. dag_id=backup_files_dag, task_id=backup_files, run_id=manual__2024-11-04T20:18:23.163142+00:00, execution_date=20241104T201823, start_date=20241104T201825, end_date=20241104T201825
[2024-11-04T20:18:25.293+0000] {taskinstance.py:340} INFO - ::group::Post task execution logs
[2024-11-04T20:18:25.294+0000] {standard_task_runner.py:124} ERROR - Failed to execute job 53 for task backup_files (Bash command failed. The command returned a non-zero exit code 1.; 105)
Traceback (most recent call last):
  File "/home/airflow/.local/lib/python3.12/site-packages/airflow/task/task_runner/standard_task_runner.py", line 117, in _start_by_fork
    ret = args.func(args, dag=self.dag)
          ^^^^^^^^^^^^^^^^^^^^^^^^^^^^^
  File "/home/airflow/.local/lib/python3.12/site-packages/airflow/cli/cli_config.py", line 49, in command
    return func(*args, **kwargs)
           ^^^^^^^^^^^^^^^^^^^^^
  File "/home/airflow/.local/lib/python3.12/site-packages/airflow/utils/cli.py", line 115, in wrapper
    return f(*args, **kwargs)
           ^^^^^^^^^^^^^^^^^^
  File "/home/airflow/.local/lib/python3.12/site-packages/airflow/cli/commands/task_command.py", line 483, in task_run
    task_return_code = _run_task_by_selected_method(args, _dag, ti)
                       ^^^^^^^^^^^^^^^^^^^^^^^^^^^^^^^^^^^^^^^^^^^^
  File "/home/airflow/.local/lib/python3.12/site-packages/airflow/cli/commands/task_command.py", line 256, in _run_task_by_selected_method
    return _run_raw_task(args, ti)
           ^^^^^^^^^^^^^^^^^^^^^^^
  File "/home/airflow/.local/lib/python3.12/site-packages/airflow/cli/commands/task_command.py", line 341, in _run_raw_task
    return ti._run_raw_task(
           ^^^^^^^^^^^^^^^^^
  File "/home/airflow/.local/lib/python3.12/site-packages/airflow/utils/session.py", line 97, in wrapper
    return func(*args, session=session, **kwargs)
           ^^^^^^^^^^^^^^^^^^^^^^^^^^^^^^^^^^^^^^
  File "/home/airflow/.local/lib/python3.12/site-packages/airflow/models/taskinstance.py", line 3004, in _run_raw_task
    return _run_raw_task(
           ^^^^^^^^^^^^^^
  File "/home/airflow/.local/lib/python3.12/site-packages/airflow/models/taskinstance.py", line 273, in _run_raw_task
    TaskInstance._execute_task_with_callbacks(
  File "/home/airflow/.local/lib/python3.12/site-packages/airflow/models/taskinstance.py", line 3158, in _execute_task_with_callbacks
    result = self._execute_task(context, task_orig)
             ^^^^^^^^^^^^^^^^^^^^^^^^^^^^^^^^^^^^^^
  File "/home/airflow/.local/lib/python3.12/site-packages/airflow/models/taskinstance.py", line 3182, in _execute_task
    return _execute_task(self, context, task_orig)
           ^^^^^^^^^^^^^^^^^^^^^^^^^^^^^^^^^^^^^^^
  File "/home/airflow/.local/lib/python3.12/site-packages/airflow/models/taskinstance.py", line 767, in _execute_task
    result = _execute_callable(context=context, **execute_callable_kwargs)
             ^^^^^^^^^^^^^^^^^^^^^^^^^^^^^^^^^^^^^^^^^^^^^^^^^^^^^^^^^^^^^
  File "/home/airflow/.local/lib/python3.12/site-packages/airflow/models/taskinstance.py", line 733, in _execute_callable
    return ExecutionCallableRunner(
           ^^^^^^^^^^^^^^^^^^^^^^^^
  File "/home/airflow/.local/lib/python3.12/site-packages/airflow/utils/operator_helpers.py", line 252, in run
    return self.func(*args, **kwargs)
           ^^^^^^^^^^^^^^^^^^^^^^^^^^
  File "/home/airflow/.local/lib/python3.12/site-packages/airflow/models/baseoperator.py", line 406, in wrapper
    return func(self, *args, **kwargs)
           ^^^^^^^^^^^^^^^^^^^^^^^^^^^
  File "/home/airflow/.local/lib/python3.12/site-packages/airflow/operators/bash.py", line 249, in execute
    raise AirflowException(
airflow.exceptions.AirflowException: Bash command failed. The command returned a non-zero exit code 1.
[2024-11-04T20:18:25.332+0000] {local_task_job_runner.py:266} INFO - Task exited with return code 1
[2024-11-04T20:18:25.343+0000] {taskinstance.py:3900} INFO - 0 downstream tasks scheduled from follow-on schedule check
[2024-11-04T20:18:25.346+0000] {local_task_job_runner.py:245} INFO - ::endgroup::
