[2024-11-04T20:22:20.166+0000] {local_task_job_runner.py:123} INFO - ::group::Pre task execution logs
[2024-11-04T20:22:20.192+0000] {taskinstance.py:2612} INFO - Dependencies all met for dep_context=non-requeueable deps ti=<TaskInstance: backup_files_dag.backup_files scheduled__2024-11-01T00:00:00+00:00 [queued]>
[2024-11-04T20:22:20.204+0000] {taskinstance.py:2612} INFO - Dependencies all met for dep_context=requeueable deps ti=<TaskInstance: backup_files_dag.backup_files scheduled__2024-11-01T00:00:00+00:00 [queued]>
[2024-11-04T20:22:20.205+0000] {taskinstance.py:2865} INFO - Starting attempt 2 of 2
[2024-11-04T20:22:20.224+0000] {taskinstance.py:2888} INFO - Executing <Task(BashOperator): backup_files> on 2024-11-01 00:00:00+00:00
[2024-11-04T20:22:20.232+0000] {warnings.py:112} WARNING - /home/***/.local/lib/python3.12/site-packages/***/task/task_runner/standard_task_runner.py:70: DeprecationWarning: This process (pid=159) is multi-threaded, use of fork() may lead to deadlocks in the child.
  pid = os.fork()

[2024-11-04T20:22:20.235+0000] {standard_task_runner.py:72} INFO - Started process 168 to run task
[2024-11-04T20:22:20.237+0000] {standard_task_runner.py:104} INFO - Running: ['***', 'tasks', 'run', 'backup_files_dag', 'backup_files', 'scheduled__2024-11-01T00:00:00+00:00', '--job-id', '56', '--raw', '--subdir', 'DAGS_FOLDER/backup_files_dag.py', '--cfg-path', '/tmp/tmp1whigzsm']
[2024-11-04T20:22:20.240+0000] {standard_task_runner.py:105} INFO - Job 56: Subtask backup_files
[2024-11-04T20:22:20.314+0000] {task_command.py:467} INFO - Running <TaskInstance: backup_files_dag.backup_files scheduled__2024-11-01T00:00:00+00:00 [running]> on host e07dba6ee931
[2024-11-04T20:22:20.427+0000] {taskinstance.py:3131} INFO - Exporting env vars: AIRFLOW_CTX_DAG_OWNER='***' AIRFLOW_CTX_DAG_ID='backup_files_dag' AIRFLOW_CTX_TASK_ID='backup_files' AIRFLOW_CTX_EXECUTION_DATE='2024-11-01T00:00:00+00:00' AIRFLOW_CTX_TRY_NUMBER='2' AIRFLOW_CTX_DAG_RUN_ID='scheduled__2024-11-01T00:00:00+00:00'
[2024-11-04T20:22:20.429+0000] {logging_mixin.py:190} INFO - Task instance is in running state
[2024-11-04T20:22:20.430+0000] {logging_mixin.py:190} INFO -  Previous state of the Task instance: queued
[2024-11-04T20:22:20.431+0000] {logging_mixin.py:190} INFO - Current task name:backup_files state:running start_date:2024-11-04 20:22:20.193556+00:00
[2024-11-04T20:22:20.431+0000] {logging_mixin.py:190} INFO - Dag name:backup_files_dag and current dag run status:running
[2024-11-04T20:22:20.432+0000] {taskinstance.py:731} INFO - ::endgroup::
[2024-11-04T20:22:20.433+0000] {subprocess.py:63} INFO - Tmp dir root location: /tmp
[2024-11-04T20:22:20.435+0000] {subprocess.py:75} INFO - Running command: ['/usr/bin/bash', '-c', 'cp -r D:\\Dev\\Airflow\\source* D:\\Dev\\Airflow\x08ackup']
[2024-11-04T20:22:20.448+0000] {subprocess.py:86} INFO - Output:
[2024-11-04T20:22:20.452+0000] {subprocess.py:93} INFO - cp: cannot stat 'D:DevAirflowsource*': No such file or directory
[2024-11-04T20:22:20.453+0000] {subprocess.py:97} INFO - Command exited with return code 1
[2024-11-04T20:22:20.469+0000] {taskinstance.py:3310} ERROR - Task failed with exception
Traceback (most recent call last):
  File "/home/airflow/.local/lib/python3.12/site-packages/airflow/models/taskinstance.py", line 767, in _execute_task
    result = _execute_callable(context=context, **execute_callable_kwargs)
             ^^^^^^^^^^^^^^^^^^^^^^^^^^^^^^^^^^^^^^^^^^^^^^^^^^^^^^^^^^^^^
  File "/home/airflow/.local/lib/python3.12/site-packages/airflow/models/taskinstance.py", line 733, in _execute_callable
    return ExecutionCallableRunner(
           ^^^^^^^^^^^^^^^^^^^^^^^^
  File "/home/airflow/.local/lib/python3.12/site-packages/airflow/utils/operator_helpers.py", line 252, in run
    return self.func(*args, **kwargs)
           ^^^^^^^^^^^^^^^^^^^^^^^^^^
  File "/home/airflow/.local/lib/python3.12/site-packages/airflow/models/baseoperator.py", line 406, in wrapper
    return func(self, *args, **kwargs)
           ^^^^^^^^^^^^^^^^^^^^^^^^^^^
  File "/home/airflow/.local/lib/python3.12/site-packages/airflow/operators/bash.py", line 249, in execute
    raise AirflowException(
airflow.exceptions.AirflowException: Bash command failed. The command returned a non-zero exit code 1.
[2024-11-04T20:22:20.476+0000] {logging_mixin.py:190} INFO - Task instance in failure state
[2024-11-04T20:22:20.477+0000] {logging_mixin.py:190} INFO - Task start:2024-11-04 20:22:20.193556+00:00 end:2024-11-04 20:22:20.475388+00:00 duration:0.281832
[2024-11-04T20:22:20.478+0000] {logging_mixin.py:190} INFO - Task:<Task(BashOperator): backup_files> dag:<DAG: backup_files_dag> dagrun:<DagRun backup_files_dag @ 2024-11-01 00:00:00+00:00: scheduled__2024-11-01T00:00:00+00:00, state:running, queued_at: 2024-11-04 20:17:16.261653+00:00. externally triggered: False>
[2024-11-04T20:22:20.479+0000] {logging_mixin.py:190} INFO - Failure caused by Bash command failed. The command returned a non-zero exit code 1.
[2024-11-04T20:22:20.480+0000] {taskinstance.py:1225} INFO - Marking task as FAILED. dag_id=backup_files_dag, task_id=backup_files, run_id=scheduled__2024-11-01T00:00:00+00:00, execution_date=20241101T000000, start_date=20241104T202220, end_date=20241104T202220
[2024-11-04T20:22:20.491+0000] {taskinstance.py:340} INFO - ::group::Post task execution logs
[2024-11-04T20:22:20.492+0000] {standard_task_runner.py:124} ERROR - Failed to execute job 56 for task backup_files (Bash command failed. The command returned a non-zero exit code 1.; 168)
Traceback (most recent call last):
  File "/home/airflow/.local/lib/python3.12/site-packages/airflow/task/task_runner/standard_task_runner.py", line 117, in _start_by_fork
    ret = args.func(args, dag=self.dag)
          ^^^^^^^^^^^^^^^^^^^^^^^^^^^^^
  File "/home/airflow/.local/lib/python3.12/site-packages/airflow/cli/cli_config.py", line 49, in command
    return func(*args, **kwargs)
           ^^^^^^^^^^^^^^^^^^^^^
  File "/home/airflow/.local/lib/python3.12/site-packages/airflow/utils/cli.py", line 115, in wrapper
    return f(*args, **kwargs)
           ^^^^^^^^^^^^^^^^^^
  File "/home/airflow/.local/lib/python3.12/site-packages/airflow/cli/commands/task_command.py", line 483, in task_run
    task_return_code = _run_task_by_selected_method(args, _dag, ti)
                       ^^^^^^^^^^^^^^^^^^^^^^^^^^^^^^^^^^^^^^^^^^^^
  File "/home/airflow/.local/lib/python3.12/site-packages/airflow/cli/commands/task_command.py", line 256, in _run_task_by_selected_method
    return _run_raw_task(args, ti)
           ^^^^^^^^^^^^^^^^^^^^^^^
  File "/home/airflow/.local/lib/python3.12/site-packages/airflow/cli/commands/task_command.py", line 341, in _run_raw_task
    return ti._run_raw_task(
           ^^^^^^^^^^^^^^^^^
  File "/home/airflow/.local/lib/python3.12/site-packages/airflow/utils/session.py", line 97, in wrapper
    return func(*args, session=session, **kwargs)
           ^^^^^^^^^^^^^^^^^^^^^^^^^^^^^^^^^^^^^^
  File "/home/airflow/.local/lib/python3.12/site-packages/airflow/models/taskinstance.py", line 3004, in _run_raw_task
    return _run_raw_task(
           ^^^^^^^^^^^^^^
  File "/home/airflow/.local/lib/python3.12/site-packages/airflow/models/taskinstance.py", line 273, in _run_raw_task
    TaskInstance._execute_task_with_callbacks(
  File "/home/airflow/.local/lib/python3.12/site-packages/airflow/models/taskinstance.py", line 3158, in _execute_task_with_callbacks
    result = self._execute_task(context, task_orig)
             ^^^^^^^^^^^^^^^^^^^^^^^^^^^^^^^^^^^^^^
  File "/home/airflow/.local/lib/python3.12/site-packages/airflow/models/taskinstance.py", line 3182, in _execute_task
    return _execute_task(self, context, task_orig)
           ^^^^^^^^^^^^^^^^^^^^^^^^^^^^^^^^^^^^^^^
  File "/home/airflow/.local/lib/python3.12/site-packages/airflow/models/taskinstance.py", line 767, in _execute_task
    result = _execute_callable(context=context, **execute_callable_kwargs)
             ^^^^^^^^^^^^^^^^^^^^^^^^^^^^^^^^^^^^^^^^^^^^^^^^^^^^^^^^^^^^^
  File "/home/airflow/.local/lib/python3.12/site-packages/airflow/models/taskinstance.py", line 733, in _execute_callable
    return ExecutionCallableRunner(
           ^^^^^^^^^^^^^^^^^^^^^^^^
  File "/home/airflow/.local/lib/python3.12/site-packages/airflow/utils/operator_helpers.py", line 252, in run
    return self.func(*args, **kwargs)
           ^^^^^^^^^^^^^^^^^^^^^^^^^^
  File "/home/airflow/.local/lib/python3.12/site-packages/airflow/models/baseoperator.py", line 406, in wrapper
    return func(self, *args, **kwargs)
           ^^^^^^^^^^^^^^^^^^^^^^^^^^^
  File "/home/airflow/.local/lib/python3.12/site-packages/airflow/operators/bash.py", line 249, in execute
    raise AirflowException(
airflow.exceptions.AirflowException: Bash command failed. The command returned a non-zero exit code 1.
[2024-11-04T20:22:20.537+0000] {local_task_job_runner.py:266} INFO - Task exited with return code 1
[2024-11-04T20:22:20.553+0000] {taskinstance.py:3900} INFO - 0 downstream tasks scheduled from follow-on schedule check
[2024-11-04T20:22:20.555+0000] {local_task_job_runner.py:245} INFO - ::endgroup::
